Workbook

Sheet Chart-1
B1: Domestic Pre-Tax Profits | C1: Federal Income Taxes | D1: Effective Tax Rate | E1: Executive Pay | F1: Stock Buybacks | G1: Dividend Payouts
B2: Five-Year Total, 2018 to 2022 (millions of dollars)
A3: 35 Profitable Corporations That Paid More To Executives Than Federal Taxes | B3: ='Chart-2'!B39 -> 277426.71 | C3: ='Chart-2'!C39 -> -1718.97 | D3: =C3/B3 -> -0.0061961229 | E3: ='Chart-2'!E39 -> 9491.61 | F3: ='Chart-2'!F39 -> 86998.993 | G3: ='Chart-2'!G39 -> 147904.71
A5: 29 Profitable Corporations That Paid More To Executives Than Federal Taxes In At Least 2 Years | B5: ='Chart-3'!B33 -> 380289.31 | C5: ='Chart-3'!C33 -> 20010.68 | D5: =C5/B5 -> 0.052619623 | E5: ='Chart-3'!E33 -> 5605.1758 | F5: ='Chart-3'!F33 -> 160483.8 | G5: ='Chart-3'!G33 -> 217210.28
A7: All 64 Corporations | B7: ='Key Findings'!R3 -> 657716.02 | C7: ='Key Findings'!Y3 -> 18291.71 | D7: =C7/B7 -> 0.027810954 | E7: ='Key Findings'!D3/1000000 -> 15096.786 | F7: ='Key Findings'!AM3 -> 247482.79 | G7: ='Key Findings'!AT3 -> 365114.99

Sheet Chart-2
A1: 35 profitable corporations that paid top executives more than they paid in federal income taxes between 2018 and 2022 | B1: Domestic Pre-Tax Profits | C1: Federal Income Taxes | D1: Effective Tax Rate | E1: Executive Pay | F1: Stock Buybacks | G1: Dividend Payouts
B2: Five-Year Total, 2018 to 2022 (millions of dollars)
A3: NextEra Energy | B3: {=INDEX('Key Findings'!R:R,Match($A3,'Key Findings'!$B:$B,0))} -> 23965 | C3: {=INDEX('Key Findings'!Y:Y,Match($A3,'Key Findings'!$B:$B,0))} -> 287 | D3: =C3/B3 -> 0.011975798 | E3: {=INDEX('Key Findings'!D:D,Match($A3,'Key Findings'!$B:$B,0))/1000000} -> 324.82315 | F3: {=INDEX('Key Findings'!AM:AM,Match($A3,'Key Findings'!$B:$B,0))} -> 0 | G3: {=INDEX('Key Findings'!AT:AT,Match($A3,'Key Findings'!$B:$B,0))} -> 13628
A4: T-Mobile US | B4: {=INDEX('Key Findings'!R:R,Match($A4,'Key Findings'!$B:$B,0))} -> 17916.13 | C4: {=INDEX('Key Findings'!Y:Y,Match($A4,'Key Findings'!$B:$B,0))} -> -80 | D4: =C4/B4 -> -0.00446525 | E4: {=INDEX('Key Findings'!D:D,Match($A4,'Key Findings'!$B:$B,0))/1000000} -> 675.16 | F4: {=INDEX('Key Findings'!AM:AM,Match($A4,'Key Findings'!$B:$B,0))} -> 23607 | G4: {=INDEX('Key Findings'!AT:AT,Match($A4,'Key Findings'!$B:$B,0))} -> 0
A5: American International Group | B5: {=INDEX('Key Findings'!R:R,Match($A5,'Key Findings'!$B:$B,0))} -> 17687 | C5: {=INDEX('Key Findings'!Y:Y,Match($A5,'Key Findings'!$B:$B,0))} -> 385 | D5: =C5/B5 -> 0.0217674 | E5: {=INDEX('Key Findings'!D:D,Match($A5,'Key Findings'!$B:$B,0))/1000000} -> 406.14313 | F5: {=INDEX('Key Findings'!AM:AM,Match($A5,'Key Findings'!$B:$B,0))} -> 10037 | G5: {=INDEX('Key Findings'!AT:AT,Match($A5,'Key Findings'!$B:$B,0))} -> 5529
A6: Duke Energy | B6: {=INDEX('Key Findings'!R:R,Match($A6,'Key Findings'!$B:$B,0))} -> 15624 | C6: {=INDEX('Key Findings'!Y:Y,Match($A6,'Key Findings'!$B:$B,0))} -> -1228 | D6: =C6/B6 -> -0.07859703 | E6: {=INDEX('Key Findings'!D:D,Match($A6,'Key Findings'!$B:$B,0))/1000000} -> 180.5561 | F6: {=INDEX('Key Findings'!AM:AM,Match($A6,'Key Findings'!$B:$B,0))} -> 0 | G6: {=INDEX('Key Findings'!AT:AT,Match($A6,'Key Findings'!$B:$B,0))} -> 14244
A7: Netflix | B7: {=INDEX('Key Findings'!R:R,Match($A7,'Key Findings'!$B:$B,0))} -> 15079.54 | C7: {=INDEX('Key Findings'!Y:Y,Match($A7,'Key Findings'!$B:$B,0))} -> 235.98 | D7: =C7/B7 -> 0.015649018 | E7: {=INDEX('Key Findings'!D:D,Match($A7,'Key Findings'!$B:$B,0))/1000000} -> 651.92517 | F7: {=INDEX('Key Findings'!AM:AM,Match($A7,'Key Findings'!$B:$B,0))} -> 600.022 | G7: {=INDEX('Key Findings'!AT:AT,Match($A7,'Key Findings'!$B:$B,0))} -> 0
A8: DISH Network | B8: {=INDEX('Key Findings'!R:R,Match($A8,'Key Findings'!$B:$B,0))} -> 12782.84 | C8: {=INDEX('Key Findings'!Y:Y,Match($A8,'Key Findings'!$B:$B,0))} -> 89.71 | D8: =C8/B8 -> 0.0070180023 | E8: {=INDEX('Key Findings'!D:D,Match($A8,'Key Findings'!$B:$B,0))/1000000} -> 164.30339 | F8: {=INDEX('Key Findings'!AM:AM,Match($A8,'Key Findings'!$B:$B,0))} -> 0 | G8: {=INDEX('Key Findings'!AT:AT,Match($A8,'Key Findings'!$B:$B,0))} -> 0
A9: Principal Financial | B9: {=INDEX('Key Findings'!R:R,Match($A9,'Key Findings'!$B:$B,0))} -> 11976.3 | C9: {=INDEX('Key Findings'!Y:Y,Match($A9,'Key Findings'!$B:$B,0))} -> 45.9 | D9: =C9/B9 -> 0.0038325693 | E9: {=INDEX('Key Findings'!D:D,Match($A9,'Key Findings'!$B:$B,0))/1000000} -> 170.20218 | F9: {=INDEX('Key Findings'!AM:AM,Match($A9,'Key Findings'!$B:$B,0))} -> 3892 | G9: {=INDEX('Key Findings'!AT:AT,Match($A9,'Key Findings'!$B:$B,0))} -> 3115.5
A10: MetLife | B10: {=INDEX('Key Findings'!R:R,Match($A10,'Key Findings'!$B:$B,0))} -> 11658 | C10: {=INDEX('Key Findings'!Y:Y,Match($A10,'Key Findings'!$B:$B,0))} -> 96 | D10: =C10/B10 -> 0.0082346886 | E10: {=INDEX('Key Findings'!D:D,Match($A10,'Key Findings'!$B:$B,0))/1000000} -> 239.63619 | F10: {=INDEX('Key Findings'!AM:AM,Match($A10,'Key Findings'!$B:$B,0))} -> 15057 | G10: {=INDEX('Key Findings'!AT:AT,Match($A10,'Key Findings'!$B:$B,0))} -> 9124
A11: American Electric Power | B11: {=INDEX('Key Findings'!R:R,Match($A11,'Key Findings'!$B:$B,0))} -> 10835.6 | C11: {=INDEX('Key Findings'!Y:Y,Match($A11,'Key Findings'!$B:$B,0))} -> -92 | D11: =C11/B11 -> -0.0084905312 | E11: {=INDEX('Key Findings'!D:D,Match($A11,'Key Findings'!$B:$B,0))/1000000} -> 157.34985 | F11: {=INDEX('Key Findings'!AM:AM,Match($A11,'Key Findings'!$B:$B,0))} -> 0 | G11: {=INDEX('Key Findings'!AT:AT,Match($A11,'Key Findings'!$B:$B,0))} -> 7195.1
A12: Kinder Morgan | B12: {=INDEX('Key Findings'!R:R,Match($A12,'Key Findings'!$B:$B,0))} -> 12867.48 | C12: {=INDEX('Key Findings'!Y:Y,Match($A12,'Key Findings'!$B:$B,0))} -> -44 | D12: =C12/B12 -> -0.003419473 | E12: {=INDEX('Key Findings'!D:D,Match($A12,'Key Findings'!$B:$B,0))/1000000} -> 117.08397 | F12: {=INDEX('Key Findings'!AM:AM,Match($A12,'Key Findings'!$B:$B,0))} -> 693 | G12: {=INDEX('Key Findings'!AT:AT,Match($A12,'Key Findings'!$B:$B,0))} -> 11246
A13: Dominion Energy | B13: {=INDEX('Key Findings'!R:R,Match($A13,'Key Findings'!$B:$B,0))} -> 10200 | C13: {=INDEX('Key Findings'!Y:Y,Match($A13,'Key Findings'!$B:$B,0))} -> -482 | D13: =C13/B13 -> -0.047254902 | E13: {=INDEX('Key Findings'!D:D,Match($A13,'Key Findings'!$B:$B,0))/1000000} -> 155.72685 | F13: {=INDEX('Key Findings'!AM:AM,Match($A13,'Key Findings'!$B:$B,0))} -> 4690 | G13: {=INDEX('Key Findings'!AT:AT,Match($A13,'Key Findings'!$B:$B,0))} -> 12286
A14: Oneok | B14: {=INDEX('Key Findings'!R:R,Match($A14,'Key Findings'!$B:$B,0))} -> 8179.16 | C14: {=INDEX('Key Findings'!Y:Y,Match($A14,'Key Findings'!$B:$B,0))} -> 54.87 | D14: =C14/B14 -> 0.0067085129 | E14: {=INDEX('Key Findings'!D:D,Match($A14,'Key Findings'!$B:$B,0))/1000000} -> 107.19934 | F14: {=INDEX('Key Findings'!AM:AM,Match($A14,'Key Findings'!$B:$B,0))} -> 0 | G14: {=INDEX('Key Findings'!AT:AT,Match($A14,'Key Findings'!$B:$B,0))} -> 7737.07
... A37: Agilent Technologies | B37: {=INDEX('Key Findings'!R:R,Match($A37,'Key Findings'!$B:$B,0))} -> 2097 | C37: {=INDEX('Key Findings'!Y:Y,Match($A37,'Key Findings'!$B:$B,0))} -> 130 | D37: =C37/B37 -> 0.061993324 | E37: {=INDEX('Key Findings'!D:D,Match($A37,'Key Findings'!$B:$B,0))/1000000} -> 149.78778 | F37: {=INDEX('Key Findings'!AM:AM,Match($A37,'Key Findings'!$B:$B,0))} -> 3541 | G37: {=INDEX('Key Findings'!AT:AT,Match($A37,'Key Findings'!$B:$B,0))} -> 1105
A39: TOTAL | B39: =SUM(B3:B37) -> 277426.71 | C39: =SUM(C3:C37) -> -1718.97 | D39: =C39/B39 -> -0.0061961229 | E39: =SUM(E3:E37) -> 9491.61 | F39: =SUM(F3:F37) -> 86998.993 | G39: =SUM(G3:G37) -> 147904.71

Sheet Chart-3
A1: 29 profitable corporations that paid top executives more than they paid in federal income taxes in at least 2 of the 5 years between 2018 and 2022 | B1: Domestic Pre-Tax Profits | C1: Federal Income Taxes | D1: Effective Tax Rate | E1: Executive Pay | F1: Stock Buybacks | G1: Dividend Payouts
B2: Five-Year Total, 2018 to 2022 (millions of dollars)
A3: AT&T | B3: {=INDEX('Key Findings'!R:R,Match($A3,'Key Findings'!$B:$B,0))} -> 96279.52 | C3: {=INDEX('Key Findings'!Y:Y,Match($A3,'Key Findings'!$B:$B,0))} -> 2536 | D3: =C3/B3 -> 0.026339973 | E3: {=INDEX('Key Findings'!D:D,Match($A3,'Key Findings'!$B:$B,0))/1000000} -> 506.15635 | F3: {=INDEX('Key Findings'!AM:AM,Match($A3,'Key Findings'!$B:$B,0))} -> 9616 | G3: {=INDEX('Key Findings'!AT:AT,Match($A3,'Key Findings'!$B:$B,0))} -> 68181
A4: General Motors | B4: {=INDEX('Key Findings'!R:R,Match($A4,'Key Findings'!$B:$B,0))} -> 33110 | C4: {=INDEX('Key Findings'!Y:Y,Match($A4,'Key Findings'!$B:$B,0))} -> 431 | D4: =C4/B4 -> 0.013017215 | E4: {=INDEX('Key Findings'!D:D,Match($A4,'Key Findings'!$B:$B,0))/1000000} -> 317.60625 | F4: {=INDEX('Key Findings'!AM:AM,Match($A4,'Key Findings'!$B:$B,0))} -> 2690 | G4: {=INDEX('Key Findings'!AT:AT,Match($A4,'Key Findings'!$B:$B,0))} -> 5844
A5: Chevron | B5: {=INDEX('Key Findings'!R:R,Match($A5,'Key Findings'!$B:$B,0))} -> 23121 | C5: {=INDEX('Key Findings'!Y:Y,Match($A5,'Key Findings'!$B:$B,0))} -> 1461 | D5: =C5/B5 -> 0.063189308 | E5: {=INDEX('Key Findings'!D:D,Match($A5,'Key Findings'!$B:$B,0))/1000000} -> 325.6514 | F5: {=INDEX('Key Findings'!AM:AM,Match($A5,'Key Findings'!$B:$B,0))} -> 10487 | G5: {=INDEX('Key Findings'!AT:AT,Match($A5,'Key Findings'!$B:$B,0))} -> 48259
A6: Marathon Petroleum | B6: {=INDEX('Key Findings'!R:R,Match($A6,'Key Findings'!$B:$B,0))} -> 22394 | C6: {=INDEX('Key Findings'!Y:Y,Match($A6,'Key Findings'!$B:$B,0))} -> 2390 | D6: =C6/B6 -> 0.10672502 | E6: {=INDEX('Key Findings'!D:D,Match($A6,'Key Findings'!$B:$B,0))/1000000} -> 271.47507 | F6: {=INDEX('Key Findings'!AM:AM,Match($A6,'Key Findings'!$B:$B,0))} -> 21813 | G6: {=INDEX('Key Findings'!AT:AT,Match($A6,'Key Findings'!$B:$B,0))} -> 6625
A7: Southern | B7: {=INDEX('Key Findings'!R:R,Match($A7,'Key Findings'!$B:$B,0))} -> 19021 | C7: {=INDEX('Key Findings'!Y:Y,Match($A7,'Key Findings'!$B:$B,0))} -> 582 | D7: =C7/B7 -> 0.03059776 | E7: {=INDEX('Key Findings'!D:D,Match($A7,'Key Findings'!$B:$B,0))/1000000} -> 251.67606 | F7: {=INDEX('Key Findings'!AM:AM,Match($A7,'Key Findings'!$B:$B,0))} -> 0 | G7: {=INDEX('Key Findings'!AT:AT,Match($A7,'Key Findings'!$B:$B,0))} -> 13364
A8: Charter Communications | B8: {=INDEX('Key Findings'!R:R,Match($A8,'Key Findings'!$B:$B,0))} -> 18849 | C8: {=INDEX('Key Findings'!Y:Y,Match($A8,'Key Findings'!$B:$B,0))} -> 1212 | D8: =C8/B8 -> 0.064300493 | E8: {=INDEX('Key Findings'!D:D,Match($A8,'Key Findings'!$B:$B,0))/1000000} -> 313.41352 | F8: {=INDEX('Key Findings'!AM:AM,Match($A8,'Key Findings'!$B:$B,0))} -> 48197 | G8: {=INDEX('Key Findings'!AT:AT,Match($A8,'Key Findings'!$B:$B,0))} -> 0
A9: Honeywell International | B9: {=INDEX('Key Findings'!R:R,Match($A9,'Key Findings'!$B:$B,0))} -> 17194 | C9: {=INDEX('Key Findings'!Y:Y,Match($A9,'Key Findings'!$B:$B,0))} -> 1480 | D9: =C9/B9 -> 0.086076538 | E9: {=INDEX('Key Findings'!D:D,Match($A9,'Key Findings'!$B:$B,0))/1000000} -> 275.60004 | F9: {=INDEX('Key Findings'!AM:AM,Match($A9,'Key Findings'!$B:$B,0))} -> 19694 | G9: {=INDEX('Key Findings'!AT:AT,Match($A9,'Key Findings'!$B:$B,0))} -> 12651
A10: FedEx | B10: {=INDEX('Key Findings'!R:R,Match($A10,'Key Findings'!$B:$B,0))} -> 16228.85 | C10: {=INDEX('Key Findings'!Y:Y,Match($A10,'Key Findings'!$B:$B,0))} -> 752 | D10: =C10/B10 -> 0.046337233 | E10: {=INDEX('Key Findings'!D:D,Match($A10,'Key Findings'!$B:$B,0))/1000000} -> 193.76712 | F10: {=INDEX('Key Findings'!AM:AM,Match($A10,'Key Findings'!$B:$B,0))} -> 5231 | G10: {=INDEX('Key Findings'!AT:AT,Match($A10,'Key Findings'!$B:$B,0))} -> 4018
A11: Pioneer Natural Resources | B11: {=INDEX('Key Findings'!R:R,Match($A11,'Key Findings'!$B:$B,0))} -> 14583 | C11: {=INDEX('Key Findings'!Y:Y,Match($A11,'Key Findings'!$B:$B,0))} -> 241 | D11: =C11/B11 -> 0.016526092 | E11: {=INDEX('Key Findings'!D:D,Match($A11,'Key Findings'!$B:$B,0))/1000000} -> 165.47204 | F11: {=INDEX('Key Findings'!AM:AM,Match($A11,'Key Findings'!$B:$B,0))} -> 2964 | G11: {=INDEX('Key Findings'!AT:AT,Match($A11,'Key Findings'!$B:$B,0))} -> 8391
A12: Exelon | B12: {=INDEX('Key Findings'!R:R,Match($A12,'Key Findings'!$B:$B,0))} -> 13096 | C12: {=INDEX('Key Findings'!Y:Y,Match($A12,'Key Findings'!$B:$B,0))} -> 635 | D12: =C12/B12 -> 0.048488088 | E12: {=INDEX('Key Findings'!D:D,Match($A12,'Key Findings'!$B:$B,0))/1000000} -> 220.54916 | F12: {=INDEX('Key Findings'!AM:AM,Match($A12,'Key Findings'!$B:$B,0))} -> 0 | G12: {=INDEX('Key Findings'!AT:AT,Match($A12,'Key Findings'!$B:$B,0))} -> 7063
A13: Hartford Financial Services | B13: {=INDEX('Key Findings'!R:R,Match($A13,'Key Findings'!$B:$B,0))} -> 11761 | C13: {=INDEX('Key Findings'!Y:Y,Match($A13,'Key Findings'!$B:$B,0))} -> 1436 | D13: =C13/B13 -> 0.12209846 | E13: {=INDEX('Key Findings'!D:D,Match($A13,'Key Findings'!$B:$B,0))/1000000} -> 180.32519 | F13: {=INDEX('Key Findings'!AM:AM,Match($A13,'Key Findings'!$B:$B,0))} -> 3602 | G13: {=INDEX('Key Findings'!AT:AT,Match($A13,'Key Findings'!$B:$B,0))} -> 2344
A14: Ally Financial | B14: {=INDEX('Key Findings'!R:R,Match($A14,'Key Findings'!$B:$B,0))} -> 13278 | C14: {=INDEX('Key Findings'!Y:Y,Match($A14,'Key Findings'!$B:$B,0))} -> 489 | D14: =C14/B14 -> 0.036827836 | E14: {=INDEX('Key Findings'!D:D,Match($A14,'Key Findings'!$B:$B,0))/1000000} -> 142.90713 | F14: {=INDEX('Key Findings'!AM:AM,Match($A14,'Key Findings'!$B:$B,0))} -> 5728 | G14: {=INDEX('Key Findings'!AT:AT,Match($A14,'Key Findings'!$B:$B,0))} -> 1679
... A31: Ecolab | B31: {=INDEX('Key Findings'!R:R,Match($A31,'Key Findings'!$B:$B,0))} -> 2045.29 | C31: {=INDEX('Key Findings'!Y:Y,Match($A31,'Key Findings'!$B:$B,0))} -> 199.29 | D31: =C31/B31 -> 0.097438505 | E31: {=INDEX('Key Findings'!D:D,Match($A31,'Key Findings'!$B:$B,0))/1000000} -> 155.69031 | F31: {=INDEX('Key Findings'!AM:AM,Match($A31,'Key Findings'!$B:$B,0))} -> 1687 | G31: {=INDEX('Key Findings'!AT:AT,Match($A31,'Key Findings'!$B:$B,0))} -> 2777.7
A33: TOTAL | B33: =SUM(B1:B31) -> 380289.31 | C33: =SUM(C3:C31) -> 20010.68 | D33: =C33/B33 -> 0.052619623 | E33: =SUM(E1:E31) -> 5605.1758 | F33: =SUM(F1:F31) -> 160483.8 | G33: =SUM(G1:G31) -> 217210.28

Sheet Chart-4
A1: Billionaires | B1: 20 Highest Paid Executives | C1: Corporation | D1: Five-Year Corporate Tax Rate | E1: Five-Year Executive Pay | F1: Five-Year Median Employee Pay | G1: Five-Year Pay Ratio | H1: 2022 | I1: 2021 | J1: 2020 | K1: 2019 | L1: 2018
H2: Executive Pay by Year
A3: Yes | B3: Elon Musk | C3: Tesla | D3: {=INDEX('Key Findings'!AF:AF,MATCH(C3,'Key Findings'!B:B,0))} -> -0.00022593764 | E3: =SUMIF('Executive Pay Breakdown'!K:K,$B3,'Executive Pay Breakdown'!M:M)+SUMIF('Executive Pay Breakdown'!O:O,$B3,'Executive Pay Breakdown'!Q:Q)+SUMIF('Executive Pay Breakdown'!S:S,$B3,'Executive Pay Breakdown'!U:U)+SUMIF('Executive Pay Breakdown'!W:W,$B3,'Executive Pay Breakdown'!Y:Y)+SUMIF('Executive Pay Breakdown'!AA:AA,$B3,'Executive Pay Breakdown'!AC:AC) -> 2284068644 | F3: {=INDEX('Key Findings'!BB:BB,MATCH(C3,'Key Findings'!B:B,0))} -> 235575 | G3: 9,696-to-1 | H3: =SUMIF('Executive Pay Breakdown'!K:K,$B3,'Executive Pay Breakdown'!M:M) -> 0 | I3: =SUMIF('Executive Pay Breakdown'!O:O,$B3,'Executive Pay Breakdown'!Q:Q) -> 0 | J3: =SUMIF('Executive Pay Breakdown'!S:S,$B3,'Executive Pay Breakdown'!U:U) -> 0 | K3: =SUMIF('Executive Pay Breakdown'!W:W,$B3,'Executive Pay Breakdown'!Y:Y) -> 23760 | L3: =SUMIF('Executive Pay Breakdown'!AA:AA,$B3,'Executive Pay Breakdown'!AC:AC) -> 2284044884
B4: John J. Legere | C4: T-Mobile US | D4: {=INDEX('Key Findings'!AF:AF,MATCH(C4,'Key Findings'!B:B,0))} -> -0.00446525 | E4: =SUMIF('Executive Pay Breakdown'!K:K,$B4,'Executive Pay Breakdown'!M:M)+SUMIF('Executive Pay Breakdown'!O:O,$B4,'Executive Pay Breakdown'!Q:Q)+SUMIF('Executive Pay Breakdown'!S:S,$B4,'Executive Pay Breakdown'!U:U)+SUMIF('Executive Pay Breakdown'!W:W,$B4,'Executive Pay Breakdown'!Y:Y)+SUMIF('Executive Pay Breakdown'!AA:AA,$B4,'Executive Pay Breakdown'!AC:AC) -> 231490784 | F4: {=INDEX('Key Findings'!BB:BB,MATCH(C4,'Key Findings'!B:B,0))} -> 329702 | G4: 702-to-1 | H4: =SUMIF('Executive Pay Breakdown'!K:K,$B4,'Executive Pay Breakdown'!M:M) -> 0 | I4: =SUMIF('Executive Pay Breakdown'!O:O,$B4,'Executive Pay Breakdown'!Q:Q) -> 0 | J4: =SUMIF('Executive Pay Breakdown'!S:S,$B4,'Executive Pay Breakdown'!U:U) -> 137195887 | K4: =SUMIF('Executive Pay Breakdown'!W:W,$B4,'Executive Pay Breakdown'!Y:Y) -> 27756690 | L4: =SUMIF('Executive Pay Breakdown'!AA:AA,$B4,'Executive Pay Breakdown'!AC:AC) -> 66538207
A5: Yes | B5: Reed Hastings | C5: Netflix | D5: {=INDEX('Key Findings'!AF:AF,MATCH(C5,'Key Findings'!B:B,0))} -> 0.015649018 | E5: =SUMIF('Executive Pay Breakdown'!K:K,$B5,'Executive Pay Breakdown'!M:M)+SUMIF('Executive Pay Breakdown'!O:O,$B5,'Executive Pay Breakdown'!Q:Q)+SUMIF('Executive Pay Breakdown'!S:S,$B5,'Executive Pay Breakdown'!U:U)+SUMIF('Executive Pay Breakdown'!W:W,$B5,'Executive Pay Breakdown'!Y:Y)+SUMIF('Executive Pay Breakdown'!AA:AA,$B5,'Executive Pay Breakdown'!AC:AC) -> 209780532 | F5: {=INDEX('Key Findings'!BB:BB,MATCH(C5,'Key Findings'!B:B,0))} -> 1044986 | G5: 201-to-1 | H5: =SUMIF('Executive Pay Breakdown'!K:K,$B5,'Executive Pay Breakdown'!M:M) -> 51073237 | I5: =SUMIF('Executive Pay Breakdown'!O:O,$B5,'Executive Pay Breakdown'!Q:Q) -> 40823725 | J5: =SUMIF('Executive Pay Breakdown'!S:S,$B5,'Executive Pay Breakdown'!U:U) -> 43226024 | K5: =SUMIF('Executive Pay Breakdown'!W:W,$B5,'Executive Pay Breakdown'!Y:Y) -> 38577129 | L5: =SUMIF('Executive Pay Breakdown'!AA:AA,$B5,'Executive Pay Breakdown'!AC:AC) -> 36080417
B6: Ted Sarandos | C6: Netflix | D6: {=INDEX('Key Findings'!AF:AF,MATCH(C6,'Key Findings'!B:B,0))} -> 0.015649018 | E6: =SUMIF('Executive Pay Breakdown'!K:K,$B6,'Executive Pay Breakdown'!M:M)+SUMIF('Executive Pay Breakdown'!O:O,$B6,'Executive Pay Breakdown'!Q:Q)+SUMIF('Executive Pay Breakdown'!S:S,$B6,'Executive Pay Breakdown'!U:U)+SUMIF('Executive Pay Breakdown'!W:W,$B6,'Executive Pay Breakdown'!Y:Y)+SUMIF('Executive Pay Breakdown'!AA:AA,$B6,'Executive Pay Breakdown'!AC:AC) -> 192171581 | F6: {=INDEX('Key Findings'!BB:BB,MATCH(C6,'Key Findings'!B:B,0))} -> 1044986 | G6: 184-to-1 | H6: =SUMIF('Executive Pay Breakdown'!K:K,$B6,'Executive Pay Breakdown'!M:M) -> 50299296 | I6: =SUMIF('Executive Pay Breakdown'!O:O,$B6,'Executive Pay Breakdown'!Q:Q) -> 38232164 | J6: =SUMIF('Executive Pay Breakdown'!S:S,$B6,'Executive Pay Breakdown'!U:U) -> 39318251 | K6: =SUMIF('Executive Pay Breakdown'!W:W,$B6,'Executive Pay Breakdown'!Y:Y) -> 34674399 | L6: =SUMIF('Executive Pay Breakdown'!AA:AA,$B6,'Executive Pay Breakdown'!AC:AC) -> 29647471
B7: G. Michael Sievert | C7: T-Mobile US | D7: {=INDEX('Key Findings'!AF:AF,MATCH(C7,'Key Findings'!B:B,0))} -> -0.00446525 | E7: =SUMIF('Executive Pay Breakdown'!K:K,$B7,'Executive Pay Breakdown'!M:M)+SUMIF('Executive Pay Breakdown'!O:O,$B7,'Executive Pay Breakdown'!Q:Q)+SUMIF('Executive Pay Breakdown'!S:S,$B7,'Executive Pay Breakdown'!U:U)+SUMIF('Executive Pay Breakdown'!W:W,$B7,'Executive Pay Breakdown'!Y:Y)+SUMIF('Executive Pay Breakdown'!AA:AA,$B7,'Executive Pay Breakdown'!AC:AC) -> 158603797 | F7: {=INDEX('Key Findings'!BB:BB,MATCH(C7,'Key Findings'!B:B,0))} -> 329702 | G7: 481-to-1 | H7: =SUMIF('Executive Pay Breakdown'!K:K,$B7,'Executive Pay Breakdown'!M:M) -> 29060048 | I7: =SUMIF('Executive Pay Breakdown'!O:O,$B7,'Executive Pay Breakdown'!Q:Q) -> 22610659 | J7: =SUMIF('Executive Pay Breakdown'!S:S,$B7,'Executive Pay Breakdown'!U:U) -> 54914014 | K7: =SUMIF('Executive Pay Breakdown'!W:W,$B7,'Executive Pay Breakdown'!Y:Y) -> 16369704 | L7: =SUMIF('Executive Pay Breakdown'!AA:AA,$B7,'Executive Pay Breakdown'!AC:AC) -> 35649372
B8: Peter Zaffino | C8: American International Group | D8: {=INDEX('Key Findings'!AF:AF,MATCH(C8,'Key Findings'!B:B,0))} -> 0.0217674 | E8: =SUMIF('Executive Pay Breakdown'!K:K,$B8,'Executive Pay Breakdown'!M:M)+SUMIF('Executive Pay Breakdown'!O:O,$B8,'Executive Pay Breakdown'!Q:Q)+SUMIF('Executive Pay Breakdown'!S:S,$B8,'Executive Pay Breakdown'!U:U)+SUMIF('Executive Pay Breakdown'!W:W,$B8,'Executive Pay Breakdown'!Y:Y)+SUMIF('Executive Pay Breakdown'!AA:AA,$B8,'Executive Pay Breakdown'!AC:AC) -> 152295198 | F8: {=INDEX('Key Findings'!BB:BB,MATCH(C8,'Key Findings'!B:B,0))} -> 360945 | G8: 422-to-1 | H8: =SUMIF('Executive Pay Breakdown'!K:K,$B8,'Executive Pay Breakdown'!M:M) -> 75314199 | I8: =SUMIF('Executive Pay Breakdown'!O:O,$B8,'Executive Pay Breakdown'!Q:Q) -> 21905220 | J8: =SUMIF('Executive Pay Breakdown'!S:S,$B8,'Executive Pay Breakdown'!U:U) -> 24066986 | K8: =SUMIF('Executive Pay Breakdown'!W:W,$B8,'Executive Pay Breakdown'!Y:Y) -> 18388334 | L8: =SUMIF('Executive Pay Breakdown'!AA:AA,$B8,'Executive Pay Breakdown'!AC:AC) -> 12620459
A9: Yes | B9: Marc Benioff | C9: Salesforce | D9: {=INDEX('Key Findings'!AF:AF,MATCH(C9,'Key Findings'!B:B,0))} -> 0.029013235 | E9: =SUMIF('Executive Pay Breakdown'!K:K,$B9,'Executive Pay Breakdown'!M:M)+SUMIF('Executive Pay Breakdown'!O:O,$B9,'Executive Pay Breakdown'!Q:Q)+SUMIF('Executive Pay Breakdown'!S:S,$B9,'Executive Pay Breakdown'!U:U)+SUMIF('Executive Pay Breakdown'!W:W,$B9,'Executive Pay Breakdown'!Y:Y)+SUMIF('Executive Pay Breakdown'!AA:AA,$B9,'Executive Pay Breakdown'!AC:AC) -> 138573120 | F9: {=INDEX('Key Findings'!BB:BB,MATCH(C9,'Key Findings'!B:B,0))} -> 855246 | G9: 162-to-1 | H9: =SUMIF('Executive Pay Breakdown'!K:K,$B9,'Executive Pay Breakdown'!M:M) -> 29868893 | I9: =SUMIF('Executive Pay Breakdown'!O:O,$B9,'Executive Pay Breakdown'!Q:Q) -> 28602112 | J9: =SUMIF('Executive Pay Breakdown'!S:S,$B9,'Executive Pay Breakdown'!U:U) -> 25740775 | K9: =SUMIF('Executive Pay Breakdown'!W:W,$B9,'Executive Pay Breakdown'!Y:Y) -> 25969494 | L9: =SUMIF('Executive Pay Breakdown'!AA:AA,$B9,'Executive Pay Breakdown'!AC:AC) -> 28391846
B10: Thomas M. Rutledge | C10: Charter Communications | D10: {=INDEX('Key Findings'!AF:AF,MATCH(C10,'Key Findings'!B:B,0))} -> 0.064300493 | E10: =SUMIF('Executive Pay Breakdown'!K:K,$B10,'Executive Pay Breakdown'!M:M)+SUMIF('Executive Pay Breakdown'!O:O,$B10,'Executive Pay Breakdown'!Q:Q)+SUMIF('Executive Pay Breakdown'!S:S,$B10,'Executive Pay Breakdown'!U:U)+SUMIF('Executive Pay Breakdown'!W:W,$B10,'Executive Pay Breakdown'!Y:Y)+SUMIF('Executive Pay Breakdown'!AA:AA,$B10,'Executive Pay Breakdown'!AC:AC) -> 136821183 | F10: {=INDEX('Key Findings'!BB:BB,MATCH(C10,'Key Findings'!B:B,0))} -> 285189 | G10: 480-to-1 | H10: =SUMIF('Executive Pay Breakdown'!K:K,$B10,'Executive Pay Breakdown'!M:M) -> 39213350 | I10: =SUMIF('Executive Pay Breakdown'!O:O,$B10,'Executive Pay Breakdown'!Q:Q) -> 41860263 | J10: =SUMIF('Executive Pay Breakdown'!S:S,$B10,'Executive Pay Breakdown'!U:U) -> 38846705 | K10: =SUMIF('Executive Pay Breakdown'!W:W,$B10,'Executive Pay Breakdown'!Y:Y) -> 8743601 | L10: =SUMIF('Executive Pay Breakdown'!AA:AA,$B10,'Executive Pay Breakdown'!AC:AC) -> 8157264
B11: James L. Robo | C11: NextEra Energy | D11: {=INDEX('Key Findings'!AF:AF,MATCH(C11,'Key Findings'!B:B,0))} -> 0.011975798 | E11: =SUMIF('Executive Pay Breakdown'!K:K,$B11,'Executive Pay Breakdown'!M:M)+SUMIF('Executive Pay Breakdown'!O:O,$B11,'Executive Pay Breakdown'!Q:Q)+SUMIF('Executive Pay Breakdown'!S:S,$B11,'Executive Pay Breakdown'!U:U)+SUMIF('Executive Pay Breakdown'!W:W,$B11,'Executive Pay Breakdown'!Y:Y)+SUMIF('Executive Pay Breakdown'!AA:AA,$B11,'Executive Pay Breakdown'!AC:AC) -> 132699000 | F11: {=INDEX('Key Findings'!BB:BB,MATCH(C11,'Key Findings'!B:B,0))} -> 664263 | G11: 200-to-1 | H11: =SUMIF('Executive Pay Breakdown'!K:K,$B11,'Executive Pay Breakdown'!M:M) -> 40406018 | I11: =SUMIF('Executive Pay Breakdown'!O:O,$B11,'Executive Pay Breakdown'!Q:Q) -> 25335936 | J11: =SUMIF('Executive Pay Breakdown'!S:S,$B11,'Executive Pay Breakdown'!U:U) -> 23720707 | K11: =SUMIF('Executive Pay Breakdown'!W:W,$B11,'Executive Pay Breakdown'!Y:Y) -> 21877597 | L11: =SUMIF('Executive Pay Breakdown'!AA:AA,$B11,'Executive Pay Breakdown'!AC:AC) -> 21358742
B12: Michael K. Wirth | C12: Chevron | D12: {=INDEX('Key Findings'!AF:AF,MATCH(C12,'Key Findings'!B:B,0))} -> 0.063189308 | E12: =SUMIF('Executive Pay Breakdown'!K:K,$B12,'Executive Pay Breakdown'!M:M)+SUMIF('Executive Pay Breakdown'!O:O,$B12,'Executive Pay Breakdown'!Q:Q)+SUMIF('Executive Pay Breakdown'!S:S,$B12,'Executive Pay Breakdown'!U:U)+SUMIF('Executive Pay Breakdown'!W:W,$B12,'Executive Pay Breakdown'!Y:Y)+SUMIF('Executive Pay Breakdown'!AA:AA,$B12,'Executive Pay Breakdown'!AC:AC) -> 128912181 | F12: {=INDEX('Key Findings'!BB:BB,MATCH(C12,'Key Findings'!B:B,0))} -> 785016 | G12: 164-to-1 | H12: =SUMIF('Executive Pay Breakdown'!K:K,$B12,'Executive Pay Breakdown'!M:M) -> 23573925 | I12: =SUMIF('Executive Pay Breakdown'!O:O,$B12,'Executive Pay Breakdown'!Q:Q) -> 22610285 | J12: =SUMIF('Executive Pay Breakdown'!S:S,$B12,'Executive Pay Breakdown'!U:U) -> 29016686 | K12: =SUMIF('Executive Pay Breakdown'!W:W,$B12,'Executive Pay Breakdown'!Y:Y) -> 33070662 | L12: =SUMIF('Executive Pay Breakdown'!AA:AA,$B12,'Executive Pay Breakdown'!AC:AC) -> 20640623
B13: Mary T. Barra | C13: General Motors | D13: {=INDEX('Key Findings'!AF:AF,MATCH(C13,'Key Findings'!B:B,0))} -> 0.013017215 | E13: =SUMIF('Executive Pay Breakdown'!K:K,$B13,'Executive Pay Breakdown'!M:M)+SUMIF('Executive Pay Breakdown'!O:O,$B13,'Executive Pay Breakdown'!Q:Q)+SUMIF('Executive Pay Breakdown'!S:S,$B13,'Executive Pay Breakdown'!U:U)+SUMIF('Executive Pay Breakdown'!W:W,$B13,'Executive Pay Breakdown'!Y:Y)+SUMIF('Executive Pay Breakdown'!AA:AA,$B13,'Executive Pay Breakdown'!AC:AC) -> 125275654 | F13: {=INDEX('Key Findings'!BB:BB,MATCH(C13,'Key Findings'!B:B,0))} -> 451597 | G13: 277-to-1 | H13: =SUMIF('Executive Pay Breakdown'!K:K,$B13,'Executive Pay Breakdown'!M:M) -> 28979570 | I13: =SUMIF('Executive Pay Breakdown'!O:O,$B13,'Executive Pay Breakdown'!Q:Q) -> 29136780 | J13: =SUMIF('Executive Pay Breakdown'!S:S,$B13,'Executive Pay Breakdown'!U:U) -> 23657987 | K13: =SUMIF('Executive Pay Breakdown'!W:W,$B13,'Executive Pay Breakdown'!Y:Y) -> 21630867 | L13: =SUMIF('Executive Pay Breakdown'!AA:AA,$B13,'Executive Pay Breakdown'!AC:AC) -> 21870450
B14: Jeffrey K. Storey | C14: Lumen Technologies | D14: {=INDEX('Key Findings'!AF:AF,MATCH(C14,'Key Findings'!B:B,0))} -> 0.031863865 | E14: =SUMIF('Executive Pay Breakdown'!K:K,$B14,'Executive Pay Breakdown'!M:M)+SUMIF('Executive Pay Breakdown'!O:O,$B14,'Executive Pay Breakdown'!Q:Q)+SUMIF('Executive Pay Breakdown'!S:S,$B14,'Executive Pay Breakdown'!U:U)+SUMIF('Executive Pay Breakdown'!W:W,$B14,'Executive Pay Breakdown'!Y:Y)+SUMIF('Executive Pay Breakdown'!AA:AA,$B14,'Executive Pay Breakdown'!AC:AC) -> 112321574 | F14: {=INDEX('Key Findings'!BB:BB,MATCH(C14,'Key Findings'!B:B,0))} -> 368248 | G14: 305-to-1 | H14: =SUMIF('Executive Pay Breakdown'!K:K,$B14,'Executive Pay Breakdown'!M:M) -> 19816806 | I14: =SUMIF('Executive Pay Breakdown'!O:O,$B14,'Executive Pay Breakdown'!Q:Q) -> 22654781 | J14: =SUMIF('Executive Pay Breakdown'!S:S,$B14,'Executive Pay Breakdown'!U:U) -> 16959233 | K14: =SUMIF('Executive Pay Breakdown'!W:W,$B14,'Executive Pay Breakdown'!Y:Y) -> 17235108 | L14: =SUMIF('Executive Pay Breakdown'!AA:AA,$B14,'Executive Pay Breakdown'!AC:AC) -> 35655646
B15: Darius Adamczyk | C15: Honeywell International | D15: {=INDEX('Key Findings'!AF:AF,MATCH(C15,'Key Findings'!B:B,0))} -> 0.086076538 | E15: =SUMIF('Executive Pay Breakdown'!K:K,$B15,'Executive Pay Breakdown'!M:M)+SUMIF('Executive Pay Breakdown'!O:O,$B15,'Executive Pay Breakdown'!Q:Q)+SUMIF('Executive Pay Breakdown'!S:S,$B15,'Executive Pay Breakdown'!U:U)+SUMIF('Executive Pay Breakdown'!W:W,$B15,'Executive Pay Breakdown'!Y:Y)+SUMIF('Executive Pay Breakdown'!AA:AA,$B15,'Executive Pay Breakdown'!AC:AC) -> 110384707 | F15: {=INDEX('Key Findings'!BB:BB,MATCH(C15,'Key Findings'!B:B,0))} -> 354324 | G15: 312-to-1 | H15: =SUMIF('Executive Pay Breakdown'!K:K,$B15,'Executive Pay Breakdown'!M:M) -> 25437598 | I15: =SUMIF('Executive Pay Breakdown'!O:O,$B15,'Executive Pay Breakdown'!Q:Q) -> 26100120 | J15: =SUMIF('Executive Pay Breakdown'!S:S,$B15,'Executive Pay Breakdown'!U:U) -> 19075281 | K15: =SUMIF('Executive Pay Breakdown'!W:W,$B15,'Executive Pay Breakdown'!Y:Y) -> 20525104 | L15: =SUMIF('Executive Pay Breakdown'!AA:AA,$B15,'Executive Pay Breakdown'!AC:AC) -> 19246604
B16: Thomas A. Fanning | C16: Southern | D16: {=INDEX('Key Findings'!AF:AF,MATCH(C16,'Key Findings'!B:B,0))} -> 0.03059776 | E16: =SUMIF('Executive Pay Breakdown'!K:K,$B16,'Executive Pay Breakdown'!M:M)+SUMIF('Executive Pay Breakdown'!O:O,$B16,'Executive Pay Breakdown'!Q:Q)+SUMIF('Executive Pay Breakdown'!S:S,$B16,'Executive Pay Breakdown'!U:U)+SUMIF('Executive Pay Breakdown'!W:W,$B16,'Executive Pay Breakdown'!Y:Y)+SUMIF('Executive Pay Breakdown'!AA:AA,$B16,'Executive Pay Breakdown'!AC:AC) -> 108579955 | F16: {=INDEX('Key Findings'!BB:BB,MATCH(C16,'Key Findings'!B:B,0))} -> 679620 | G16: 160-to-1 | H16: =SUMIF('Executive Pay Breakdown'!K:K,$B16,'Executive Pay Breakdown'!M:M) -> 24006670 | I16: =SUMIF('Executive Pay Breakdown'!O:O,$B16,'Executive Pay Breakdown'!Q:Q) -> 21243559 | J16: =SUMIF('Executive Pay Breakdown'!S:S,$B16,'Executive Pay Breakdown'!U:U) -> 22366850 | K16: =SUMIF('Executive Pay Breakdown'!W:W,$B16,'Executive Pay Breakdown'!Y:Y) -> 27865185 | L16: =SUMIF('Executive Pay Breakdown'!AA:AA,$B16,'Executive Pay Breakdown'!AC:AC) -> 13097691
B17: Juan Ricardo Luciano | C17: Archer Daniels Midland | D17: {=INDEX('Key Findings'!AF:AF,MATCH(C17,'Key Findings'!B:B,0))} -> 0.09336413 | E17: =SUMIF('Executive Pay Breakdown'!K:K,$B17,'Executive Pay Breakdown'!M:M)+SUMIF('Executive Pay Breakdown'!O:O,$B17,'Executive Pay Breakdown'!Q:Q)+SUMIF('Executive Pay Breakdown'!S:S,$B17,'Executive Pay Breakdown'!U:U)+SUMIF('Executive Pay Breakdown'!W:W,$B17,'Executive Pay Breakdown'!Y:Y)+SUMIF('Executive Pay Breakdown'!AA:AA,$B17,'Executive Pay Breakdown'!AC:AC) -> 108030407 | F17: {=INDEX('Key Findings'!BB:BB,MATCH(C17,'Key Findings'!B:B,0))} -> 329904 | G17: 327-to-1 | H17: =SUMIF('Executive Pay Breakdown'!K:K,$B17,'Executive Pay Breakdown'!M:M) -> 24749178 | I17: =SUMIF('Executive Pay Breakdown'!O:O,$B17,'Executive Pay Breakdown'!Q:Q) -> 23508841 | J17: =SUMIF('Executive Pay Breakdown'!S:S,$B17,'Executive Pay Breakdown'!U:U) -> 21994433 | K17: =SUMIF('Executive Pay Breakdown'!W:W,$B17,'Executive Pay Breakdown'!Y:Y) -> 18140421 | L17: =SUMIF('Executive Pay Breakdown'!AA:AA,$B17,'Executive Pay Breakdown'!AC:AC) -> 19637534
B18: John T. Stankey | C18: AT&T | D18: {=INDEX('Key Findings'!AF:AF,MATCH(C18,'Key Findings'!B:B,0))} -> 0.026339973 | E18: =SUMIF('Executive Pay Breakdown'!K:K,$B18,'Executive Pay Breakdown'!M:M)+SUMIF('Executive Pay Breakdown'!O:O,$B18,'Executive Pay Breakdown'!Q:Q)+SUMIF('Executive Pay Breakdown'!S:S,$B18,'Executive Pay Breakdown'!U:U)+SUMIF('Executive Pay Breakdown'!W:W,$B18,'Executive Pay Breakdown'!Y:Y)+SUMIF('Executive Pay Breakdown'!AA:AA,$B18,'Executive Pay Breakdown'!AC:AC) -> 107783233 | F18: {=INDEX('Key Findings'!BB:BB,MATCH(C18,'Key Findings'!B:B,0))} -> 495922 | G18: 217-to-1 | H18: =SUMIF('Executive Pay Breakdown'!K:K,$B18,'Executive Pay Breakdown'!M:M) -> 22915526 | I18: =SUMIF('Executive Pay Breakdown'!O:O,$B18,'Executive Pay Breakdown'!Q:Q) -> 24820879 | J18: =SUMIF('Executive Pay Breakdown'!S:S,$B18,'Executive Pay Breakdown'!U:U) -> 21020917 | K18: =SUMIF('Executive Pay Breakdown'!W:W,$B18,'Executive Pay Breakdown'!Y:Y) -> 22473006 | L18: =SUMIF('Executive Pay Breakdown'!AA:AA,$B18,'Executive Pay Breakdown'!AC:AC) -> 16552905
B19: Randall L. Stephenson | C19: AT&T | D19: {=INDEX('Key Findings'!AF:AF,MATCH(C19,'Key Findings'!B:B,0))} -> 0.026339973 | E19: =SUMIF('Executive Pay Breakdown'!K:K,$B19,'Executive Pay Breakdown'!M:M)+SUMIF('Executive Pay Breakdown'!O:O,$B19,'Executive Pay Breakdown'!Q:Q)+SUMIF('Executive Pay Breakdown'!S:S,$B19,'Executive Pay Breakdown'!U:U)+SUMIF('Executive Pay Breakdown'!W:W,$B19,'Executive Pay Breakdown'!Y:Y)+SUMIF('Executive Pay Breakdown'!AA:AA,$B19,'Executive Pay Breakdown'!AC:AC) -> 106651170 | F19: {=INDEX('Key Findings'!BB:BB,MATCH(C19,'Key Findings'!B:B,0))} -> 495922 | G19: 215-to-1 | H19: =SUMIF('Executive Pay Breakdown'!K:K,$B19,'Executive Pay Breakdown'!M:M) -> 0 | I19: =SUMIF('Executive Pay Breakdown'!O:O,$B19,'Executive Pay Breakdown'!Q:Q) -> 16345499 | J19: =SUMIF('Executive Pay Breakdown'!S:S,$B19,'Executive Pay Breakdown'!U:U) -> 29154628 | K19: =SUMIF('Executive Pay Breakdown'!W:W,$B19,'Executive Pay Breakdown'!Y:Y) -> 32032925 | L19: =SUMIF('Executive Pay Breakdown'!AA:AA,$B19,'Executive Pay Breakdown'!AC:AC) -> 29118118
A20: Yes | B20: Charles W. Ergen | C20: DISH Network | D20: {=INDEX('Key Findings'!AF:AF,MATCH(C20,'Key Findings'!B:B,0))} -> 0.0070180023 | E20: =SUMIF('Executive Pay Breakdown'!K:K,$B20,'Executive Pay Breakdown'!M:M)+SUMIF('Executive Pay Breakdown'!O:O,$B20,'Executive Pay Breakdown'!Q:Q)+SUMIF('Executive Pay Breakdown'!S:S,$B20,'Executive Pay Breakdown'!U:U)+SUMIF('Executive Pay Breakdown'!W:W,$B20,'Executive Pay Breakdown'!Y:Y)+SUMIF('Executive Pay Breakdown'!AA:AA,$B20,'Executive Pay Breakdown'!AC:AC) -> 106511754 | F20: {=INDEX('Key Findings'!BB:BB,MATCH(C20,'Key Findings'!B:B,0))} -> 296500 | G20: 359-to-1 | H20: =SUMIF('Executive Pay Breakdown'!K:K,$B20,'Executive Pay Breakdown'!M:M) -> 3219778 | I20: =SUMIF('Executive Pay Breakdown'!O:O,$B20,'Executive Pay Breakdown'!Q:Q) -> 3060317 | J20: =SUMIF('Executive Pay Breakdown'!S:S,$B20,'Executive Pay Breakdown'!U:U) -> 94761246 | K20: =SUMIF('Executive Pay Breakdown'!W:W,$B20,'Executive Pay Breakdown'!Y:Y) -> 2357756 | L20: =SUMIF('Executive Pay Breakdown'!AA:AA,$B20,'Executive Pay Breakdown'!AC:AC) -> 3112657
B21: Greg Peters | C21: Netflix | D21: {=INDEX('Key Findings'!AF:AF,MATCH(C21,'Key Findings'!B:B,0))} -> 0.015649018 | E21: =SUMIF('Executive Pay Breakdown'!K:K,$B21,'Executive Pay Breakdown'!M:M)+SUMIF('Executive Pay Breakdown'!O:O,$B21,'Executive Pay Breakdown'!Q:Q)+SUMIF('Executive Pay Breakdown'!S:S,$B21,'Executive Pay Breakdown'!U:U)+SUMIF('Executive Pay Breakdown'!W:W,$B21,'Executive Pay Breakdown'!Y:Y)+SUMIF('Executive Pay Breakdown'!AA:AA,$B21,'Executive Pay Breakdown'!AC:AC) -> 102753950 | F21: {=INDEX('Key Findings'!BB:BB,MATCH(C21,'Key Findings'!B:B,0))} -> 1044986 | G21: 98-to-1 | H21: =SUMIF('Executive Pay Breakdown'!K:K,$B21,'Executive Pay Breakdown'!M:M) -> 28129263 | I21: =SUMIF('Executive Pay Breakdown'!O:O,$B21,'Executive Pay Breakdown'!Q:Q) -> 20371393 | J21: =SUMIF('Executive Pay Breakdown'!S:S,$B21,'Executive Pay Breakdown'!U:U) -> 20805995 | K21: =SUMIF('Executive Pay Breakdown'!W:W,$B21,'Executive Pay Breakdown'!Y:Y) -> 18628710 | L21: =SUMIF('Executive Pay Breakdown'!AA:AA,$B21,'Executive Pay Breakdown'!AC:AC) -> 14818589
B22: Jeffrey W. Martin | C22: Sempra Energy | D22: {=INDEX('Key Findings'!AF:AF,MATCH(C22,'Key Findings'!B:B,0))} -> 0.001160389 | E22: =SUMIF('Executive Pay Breakdown'!K:K,$B22,'Executive Pay Breakdown'!M:M)+SUMIF('Executive Pay Breakdown'!O:O,$B22,'Executive Pay Breakdown'!Q:Q)+SUMIF('Executive Pay Breakdown'!S:S,$B22,'Executive Pay Breakdown'!U:U)+SUMIF('Executive Pay Breakdown'!W:W,$B22,'Executive Pay Breakdown'!Y:Y)+SUMIF('Executive Pay Breakdown'!AA:AA,$B22,'Executive Pay Breakdown'!AC:AC) -> 95596632 | F22: {=INDEX('Key Findings'!BB:BB,MATCH(C22,'Key Findings'!B:B,0))} -> 685315 | G22: 139-to-1 | H22: =SUMIF('Executive Pay Breakdown'!K:K,$B22,'Executive Pay Breakdown'!M:M) -> 18608094 | I22: =SUMIF('Executive Pay Breakdown'!O:O,$B22,'Executive Pay Breakdown'!Q:Q) -> 24675982 | J22: =SUMIF('Executive Pay Breakdown'!S:S,$B22,'Executive Pay Breakdown'!U:U) -> 23181719 | K22: =SUMIF('Executive Pay Breakdown'!W:W,$B22,'Executive Pay Breakdown'!Y:Y) -> 19806346 | L22: =SUMIF('Executive Pay Breakdown'!AA:AA,$B22,'Executive Pay Breakdown'!AC:AC) -> 9324491

Sheet Chart-5
A1: Billionaires | B1: Fastest Growing Executive Pay | C1: Corporate Allegiance | D1: Executive 5-Year Wage Growth | F1: Median Worker 5-Year Wage Growth | I1: Five-Year Executive Pay | K1: 2022 | L1: 2021 | M1: 2020 | N1: 2019 | O1: 2018
D2: ($) | E2: (%) | F2: ($) | G2: (%) | K2: Executive Pay by Year
B3: Christopher L. Winfrey | C3: Charter Communications | D3: =K3-O3 -> 13495699 | E3: =K3/O3-1 -> 6.3322393 | F3: {=INDEX('Key Findings'!BC:BC,MATCH(C3,'Key Findings'!B:B,0))-INDEX('Key Findings'!BG:BG,MATCH(C3,'Key Findings'!B:B,0))} -> -131 | G3: {=INDEX('Key Findings'!BC:BC,MATCH(C3,'Key Findings'!B:B,0))/INDEX('Key Findings'!BG:BG,MATCH(C3,'Key Findings'!B:B,0))-1} -> -0.0023578114 | I3: =SUMIF('Executive Pay Breakdown'!K:K,$B3,'Executive Pay Breakdown'!M:M)+SUMIF('Executive Pay Breakdown'!O:O,$B3,'Executive Pay Breakdown'!Q:Q)+SUMIF('Executive Pay Breakdown'!S:S,$B3,'Executive Pay Breakdown'!U:U)+SUMIF('Executive Pay Breakdown'!W:W,$B3,'Executive Pay Breakdown'!Y:Y)+SUMIF('Executive Pay Breakdown'!AA:AA,$B3,'Executive Pay Breakdown'!AC:AC) -> 43654124 | K3: =SUMIF('Executive Pay Breakdown'!K:K,$B3,'Executive Pay Breakdown'!M:M) -> 15626967 | L3: =SUMIF('Executive Pay Breakdown'!O:O,$B3,'Executive Pay Breakdown'!Q:Q) -> 11685716 | M3: =SUMIF('Executive Pay Breakdown'!S:S,$B3,'Executive Pay Breakdown'!U:U) -> 11737410 | N3: =SUMIF('Executive Pay Breakdown'!W:W,$B3,'Executive Pay Breakdown'!Y:Y) -> 2472763 | O3: =SUMIF('Executive Pay Breakdown'!AA:AA,$B3,'Executive Pay Breakdown'!AC:AC) -> 2131268
B4: Peter Zaffino | C4: American International Group | D4: =K4-O4 -> 62693740 | E4: =K4/O4-1 -> 4.9676276 | F4: {=INDEX('Key Findings'!BC:BC,MATCH(C4,'Key Findings'!B:B,0))-INDEX('Key Findings'!BG:BG,MATCH(C4,'Key Findings'!B:B,0))} -> 17800 | G4: {=INDEX('Key Findings'!BC:BC,MATCH(C4,'Key Findings'!B:B,0))/INDEX('Key Findings'!BG:BG,MATCH(C4,'Key Findings'!B:B,0))-1} -> 0.2679109 | I4: =SUMIF('Executive Pay Breakdown'!K:K,$B4,'Executive Pay Breakdown'!M:M)+SUMIF('Executive Pay Breakdown'!O:O,$B4,'Executive Pay Breakdown'!Q:Q)+SUMIF('Executive Pay Breakdown'!S:S,$B4,'Executive Pay Breakdown'!U:U)+SUMIF('Executive Pay Breakdown'!W:W,$B4,'Executive Pay Breakdown'!Y:Y)+SUMIF('Executive Pay Breakdown'!AA:AA,$B4,'Executive Pay Breakdown'!AC:AC) -> 152295198 | K4: =SUMIF('Executive Pay Breakdown'!K:K,$B4,'Executive Pay Breakdown'!M:M) -> 75314199 | L4: =SUMIF('Executive Pay Breakdown'!O:O,$B4,'Executive Pay Breakdown'!Q:Q) -> 21905220 | M4: =SUMIF('Executive Pay Breakdown'!S:S,$B4,'Executive Pay Breakdown'!U:U) -> 24066986 | N4: =SUMIF('Executive Pay Breakdown'!W:W,$B4,'Executive Pay Breakdown'!Y:Y) -> 18388334 | O4: =SUMIF('Executive Pay Breakdown'!AA:AA,$B4,'Executive Pay Breakdown'!AC:AC) -> 12620459
B5: Thomas M. Rutledge | C5: Charter Communications | D5: =K5-O5 -> 31056086 | E5: =K5/O5-1 -> 3.8071694 | F5: {=INDEX('Key Findings'!BC:BC,MATCH(C5,'Key Findings'!B:B,0))-INDEX('Key Findings'!BG:BG,MATCH(C5,'Key Findings'!B:B,0))} -> -131 | G5: {=INDEX('Key Findings'!BC:BC,MATCH(C5,'Key Findings'!B:B,0))/INDEX('Key Findings'!BG:BG,MATCH(C5,'Key Findings'!B:B,0))-1} -> -0.0023578114 | I5: =SUMIF('Executive Pay Breakdown'!K:K,$B5,'Executive Pay Breakdown'!M:M)+SUMIF('Executive Pay Breakdown'!O:O,$B5,'Executive Pay Breakdown'!Q:Q)+SUMIF('Executive Pay Breakdown'!S:S,$B5,'Executive Pay Breakdown'!U:U)+SUMIF('Executive Pay Breakdown'!W:W,$B5,'Executive Pay Breakdown'!Y:Y)+SUMIF('Executive Pay Breakdown'!AA:AA,$B5,'Executive Pay Breakdown'!AC:AC) -> 136821183 | K5: =SUMIF('Executive Pay Breakdown'!K:K,$B5,'Executive Pay Breakdown'!M:M) -> 39213350 | L5: =SUMIF('Executive Pay Breakdown'!O:O,$B5,'Executive Pay Breakdown'!Q:Q) -> 41860263 | M5: =SUMIF('Executive Pay Breakdown'!S:S,$B5,'Executive Pay Breakdown'!U:U) -> 38846705 | N5: =SUMIF('Executive Pay Breakdown'!W:W,$B5,'Executive Pay Breakdown'!Y:Y) -> 8743601 | O5: =SUMIF('Executive Pay Breakdown'!AA:AA,$B5,'Executive Pay Breakdown'!AC:AC) -> 8157264
B6: Garrick J. Rochow | C6: CMS Energy | D6: =K6-O6 -> 6851282 | E6: =K6/O6-1 -> 3.6935887 | F6: {=INDEX('Key Findings'!BC:BC,MATCH(C6,'Key Findings'!B:B,0))-INDEX('Key Findings'!BG:BG,MATCH(C6,'Key Findings'!B:B,0))} -> 16864 | G6: {=INDEX('Key Findings'!BC:BC,MATCH(C6,'Key Findings'!B:B,0))/INDEX('Key Findings'!BG:BG,MATCH(C6,'Key Findings'!B:B,0))-1} -> 0.15890695 | I6: =SUMIF('Executive Pay Breakdown'!K:K,$B6,'Executive Pay Breakdown'!M:M)+SUMIF('Executive Pay Breakdown'!O:O,$B6,'Executive Pay Breakdown'!Q:Q)+SUMIF('Executive Pay Breakdown'!S:S,$B6,'Executive Pay Breakdown'!U:U)+SUMIF('Executive Pay Breakdown'!W:W,$B6,'Executive Pay Breakdown'!Y:Y)+SUMIF('Executive Pay Breakdown'!AA:AA,$B6,'Executive Pay Breakdown'!AC:AC) -> 22050819 | K6: =SUMIF('Executive Pay Breakdown'!K:K,$B6,'Executive Pay Breakdown'!M:M) -> 8706194 | L6: =SUMIF('Executive Pay Breakdown'!O:O,$B6,'Executive Pay Breakdown'!Q:Q) -> 6871068 | M6: =SUMIF('Executive Pay Breakdown'!S:S,$B6,'Executive Pay Breakdown'!U:U) -> 2615131 | N6: =SUMIF('Executive Pay Breakdown'!W:W,$B6,'Executive Pay Breakdown'!Y:Y) -> 2003514 | O6: =SUMIF('Executive Pay Breakdown'!AA:AA,$B6,'Executive Pay Breakdown'!AC:AC) -> 1854912
B7: Bob Frenzel | C7: Xcel Energy | D7: =K7-O7 -> 7994414 | E7: =K7/O7-1 -> 3.439693 | F7: {=INDEX('Key Findings'!BC:BC,MATCH(C7,'Key Findings'!B:B,0))-INDEX('Key Findings'!BG:BG,MATCH(C7,'Key Findings'!B:B,0))} -> 10905 | G7: {=INDEX('Key Findings'!BC:BC,MATCH(C7,'Key Findings'!B:B,0))/INDEX('Key Findings'!BG:BG,MATCH(C7,'Key Findings'!B:B,0))-1} -> 0.10009546 | I7: =SUMIF('Executive Pay Breakdown'!K:K,$B7,'Executive Pay Breakdown'!M:M)+SUMIF('Executive Pay Breakdown'!O:O,$B7,'Executive Pay Breakdown'!Q:Q)+SUMIF('Executive Pay Breakdown'!S:S,$B7,'Executive Pay Breakdown'!U:U)+SUMIF('Executive Pay Breakdown'!W:W,$B7,'Executive Pay Breakdown'!Y:Y)+SUMIF('Executive Pay Breakdown'!AA:AA,$B7,'Executive Pay Breakdown'!AC:AC) -> 28150026 | K7: =SUMIF('Executive Pay Breakdown'!K:K,$B7,'Executive Pay Breakdown'!M:M) -> 10318579 | L7: =SUMIF('Executive Pay Breakdown'!O:O,$B7,'Executive Pay Breakdown'!Q:Q) -> 8350364 | M7: =SUMIF('Executive Pay Breakdown'!S:S,$B7,'Executive Pay Breakdown'!U:U) -> 4052934 | N7: =SUMIF('Executive Pay Breakdown'!W:W,$B7,'Executive Pay Breakdown'!Y:Y) -> 3103984 | O7: =SUMIF('Executive Pay Breakdown'!AA:AA,$B7,'Executive Pay Breakdown'!AC:AC) -> 2324165
B8: Brian D. Chambers | C8: Owens Corning | D8: =K8-O8 -> 8329464 | E8: =K8/O8-1 -> 3.1427314 | F8: {=INDEX('Key Findings'!BC:BC,MATCH(C8,'Key Findings'!B:B,0))-INDEX('Key Findings'!BG:BG,MATCH(C8,'Key Findings'!B:B,0))} -> -191 | G8: {=INDEX('Key Findings'!BC:BC,MATCH(C8,'Key Findings'!B:B,0))/INDEX('Key Findings'!BG:BG,MATCH(C8,'Key Findings'!B:B,0))-1} -> -0.0031524915 | I8: =SUMIF('Executive Pay Breakdown'!K:K,$B8,'Executive Pay Breakdown'!M:M)+SUMIF('Executive Pay Breakdown'!O:O,$B8,'Executive Pay Breakdown'!Q:Q)+SUMIF('Executive Pay Breakdown'!S:S,$B8,'Executive Pay Breakdown'!U:U)+SUMIF('Executive Pay Breakdown'!W:W,$B8,'Executive Pay Breakdown'!Y:Y)+SUMIF('Executive Pay Breakdown'!AA:AA,$B8,'Executive Pay Breakdown'!AC:AC) -> 37048505 | K8: =SUMIF('Executive Pay Breakdown'!K:K,$B8,'Executive Pay Breakdown'!M:M) -> 10979854 | L8: =SUMIF('Executive Pay Breakdown'!O:O,$B8,'Executive Pay Breakdown'!Q:Q) -> 9782143 | M8: =SUMIF('Executive Pay Breakdown'!S:S,$B8,'Executive Pay Breakdown'!U:U) -> 7549789 | N8: =SUMIF('Executive Pay Breakdown'!W:W,$B8,'Executive Pay Breakdown'!Y:Y) -> 6086329 | O8: =SUMIF('Executive Pay Breakdown'!AA:AA,$B8,'Executive Pay Breakdown'!AC:AC) -> 2650390
B9: Timothy P. Cawley | C9: Consolidated Edison | D9: =K9-O9 -> 7206643 | E9: =K9/O9-1 -> 3.0208249 | F9: {=INDEX('Key Findings'!BC:BC,MATCH(C9,'Key Findings'!B:B,0))-INDEX('Key Findings'!BG:BG,MATCH(C9,'Key Findings'!B:B,0))} -> 30439 | G9: {=INDEX('Key Findings'!BC:BC,MATCH(C9,'Key Findings'!B:B,0))/INDEX('Key Findings'!BG:BG,MATCH(C9,'Key Findings'!B:B,0))-1} -> 0.2859384 | I9: =SUMIF('Executive Pay Breakdown'!K:K,$B9,'Executive Pay Breakdown'!M:M)+SUMIF('Executive Pay Breakdown'!O:O,$B9,'Executive Pay Breakdown'!Q:Q)+SUMIF('Executive Pay Breakdown'!S:S,$B9,'Executive Pay Breakdown'!U:U)+SUMIF('Executive Pay Breakdown'!W:W,$B9,'Executive Pay Breakdown'!Y:Y)+SUMIF('Executive Pay Breakdown'!AA:AA,$B9,'Executive Pay Breakdown'!AC:AC) -> 26212426 | K9: =SUMIF('Executive Pay Breakdown'!K:K,$B9,'Executive Pay Breakdown'!M:M) -> 9592297 | L9: =SUMIF('Executive Pay Breakdown'!O:O,$B9,'Executive Pay Breakdown'!Q:Q) -> 8841587 | M9: =SUMIF('Executive Pay Breakdown'!S:S,$B9,'Executive Pay Breakdown'!U:U) -> 2766656 | N9: =SUMIF('Executive Pay Breakdown'!W:W,$B9,'Executive Pay Breakdown'!Y:Y) -> 2626232 | O9: =SUMIF('Executive Pay Breakdown'!AA:AA,$B9,'Executive Pay Breakdown'!AC:AC) -> 2385654
B10: Christophe Beck | C10: Ecolab | D10: =K10-O10 -> 6335022 | E10: =K10/O10-1 -> 2.6557516 | F10: {=INDEX('Key Findings'!BC:BC,MATCH(C10,'Key Findings'!B:B,0))-INDEX('Key Findings'!BG:BG,MATCH(C10,'Key Findings'!B:B,0))} -> 1444 | G10: {=INDEX('Key Findings'!BC:BC,MATCH(C10,'Key Findings'!B:B,0))/INDEX('Key Findings'!BG:BG,MATCH(C10,'Key Findings'!B:B,0))-1} -> 0.02660035 | I10: =SUMIF('Executive Pay Breakdown'!K:K,$B10,'Executive Pay Breakdown'!M:M)+SUMIF('Executive Pay Breakdown'!O:O,$B10,'Executive Pay Breakdown'!Q:Q)+SUMIF('Executive Pay Breakdown'!S:S,$B10,'Executive Pay Breakdown'!U:U)+SUMIF('Executive Pay Breakdown'!W:W,$B10,'Executive Pay Breakdown'!Y:Y)+SUMIF('Executive Pay Breakdown'!AA:AA,$B10,'Executive Pay Breakdown'!AC:AC) -> 30815796 | K10: =SUMIF('Executive Pay Breakdown'!K:K,$B10,'Executive Pay Breakdown'!M:M) -> 8720419 | L10: =SUMIF('Executive Pay Breakdown'!O:O,$B10,'Executive Pay Breakdown'!Q:Q) -> 8365888 | M10: =SUMIF('Executive Pay Breakdown'!S:S,$B10,'Executive Pay Breakdown'!U:U) -> 6445060 | N10: =SUMIF('Executive Pay Breakdown'!W:W,$B10,'Executive Pay Breakdown'!Y:Y) -> 4899032 | O10: =SUMIF('Executive Pay Breakdown'!AA:AA,$B10,'Executive Pay Breakdown'!AC:AC) -> 2385397
B11: James D. Farley Jr. | C11: Ford Motor | D11: =K11-O11 -> 15135558 | E11: =K11/O11-1 -> 2.5826006 | F11: {=INDEX('Key Findings'!BC:BC,MATCH(C11,'Key Findings'!B:B,0))-INDEX('Key Findings'!BG:BG,MATCH(C11,'Key Findings'!B:B,0))} -> 10375 | G11: {=INDEX('Key Findings'!BC:BC,MATCH(C11,'Key Findings'!B:B,0))/INDEX('Key Findings'!BG:BG,MATCH(C11,'Key Findings'!B:B,0))-1} -> 0.16131289 | I11: =SUMIF('Executive Pay Breakdown'!K:K,$B11,'Executive Pay Breakdown'!M:M)+SUMIF('Executive Pay Breakdown'!O:O,$B11,'Executive Pay Breakdown'!Q:Q)+SUMIF('Executive Pay Breakdown'!S:S,$B11,'Executive Pay Breakdown'!U:U)+SUMIF('Executive Pay Breakdown'!W:W,$B11,'Executive Pay Breakdown'!Y:Y)+SUMIF('Executive Pay Breakdown'!AA:AA,$B11,'Executive Pay Breakdown'!AC:AC) -> 69833441 | K11: =SUMIF('Executive Pay Breakdown'!K:K,$B11,'Executive Pay Breakdown'!M:M) -> 20996146 | L11: =SUMIF('Executive Pay Breakdown'!O:O,$B11,'Executive Pay Breakdown'!Q:Q) -> 22813174 | M11: =SUMIF('Executive Pay Breakdown'!S:S,$B11,'Executive Pay Breakdown'!U:U) -> 11802054 | N11: =SUMIF('Executive Pay Breakdown'!W:W,$B11,'Executive Pay Breakdown'!Y:Y) -> 8361479 | O11: =SUMIF('Executive Pay Breakdown'!AA:AA,$B11,'Executive Pay Breakdown'!AC:AC) -> 5860588
B12: John W. Ketchum | C12: NextEra Energy | D12: =K12-O12 -> 12436260 | E12: =K12/O12-1 -> 2.4982096 | F12: {=INDEX('Key Findings'!BC:BC,MATCH(C12,'Key Findings'!B:B,0))-INDEX('Key Findings'!BG:BG,MATCH(C12,'Key Findings'!B:B,0))} -> 16081 | G12: {=INDEX('Key Findings'!BC:BC,MATCH(C12,'Key Findings'!B:B,0))/INDEX('Key Findings'!BG:BG,MATCH(C12,'Key Findings'!B:B,0))-1} -> 0.12827344 | I12: =SUMIF('Executive Pay Breakdown'!K:K,$B12,'Executive Pay Breakdown'!M:M)+SUMIF('Executive Pay Breakdown'!O:O,$B12,'Executive Pay Breakdown'!Q:Q)+SUMIF('Executive Pay Breakdown'!S:S,$B12,'Executive Pay Breakdown'!U:U)+SUMIF('Executive Pay Breakdown'!W:W,$B12,'Executive Pay Breakdown'!Y:Y)+SUMIF('Executive Pay Breakdown'!AA:AA,$B12,'Executive Pay Breakdown'!AC:AC) -> 51569148 | K12: =SUMIF('Executive Pay Breakdown'!K:K,$B12,'Executive Pay Breakdown'!M:M) -> 17414329 | L12: =SUMIF('Executive Pay Breakdown'!O:O,$B12,'Executive Pay Breakdown'!Q:Q) -> 15507153 | M12: =SUMIF('Executive Pay Breakdown'!S:S,$B12,'Executive Pay Breakdown'!U:U) -> 7518782 | N12: =SUMIF('Executive Pay Breakdown'!W:W,$B12,'Executive Pay Breakdown'!Y:Y) -> 6150815 | O12: =SUMIF('Executive Pay Breakdown'!AA:AA,$B12,'Executive Pay Breakdown'!AC:AC) -> 4978069
B15: Gary Swidler | C15: Match Group | I15: =SUMIF('Executive Pay Breakdown'!K:K,$B15,'Executive Pay Breakdown'!M:M)+SUMIF('Executive Pay Breakdown'!O:O,$B15,'Executive Pay Breakdown'!Q:Q)+SUMIF('Executive Pay Breakdown'!S:S,$B15,'Executive Pay Breakdown'!U:U)+SUMIF('Executive Pay Breakdown'!W:W,$B15,'Executive Pay Breakdown'!Y:Y)+SUMIF('Executive Pay Breakdown'!AA:AA,$B15,'Executive Pay Breakdown'!AC:AC) -> 56837602 | K15: =SUMIF('Executive Pay Breakdown'!K:K,$B15,'Executive Pay Breakdown'!M:M) -> 23677633 | L15: =SUMIF('Executive Pay Breakdown'!O:O,$B15,'Executive Pay Breakdown'!Q:Q) -> 15367669 | M15: =SUMIF('Executive Pay Breakdown'!S:S,$B15,'Executive Pay Breakdown'!U:U) -> 8730701 | N15: =SUMIF('Executive Pay Breakdown'!W:W,$B15,'Executive Pay Breakdown'!Y:Y) -> 5404149 | O15: =SUMIF('Executive Pay Breakdown'!AA:AA,$B15,'Executive Pay Breakdown'!AC:AC) -> 3657450
B16: Jared F. Sine | C16: Match Group | I16: =SUMIF('Executive Pay Breakdown'!K:K,$B16,'Executive Pay Breakdown'!M:M)+SUMIF('Executive Pay Breakdown'!O:O,$B16,'Executive Pay Breakdown'!Q:Q)+SUMIF('Executive Pay Breakdown'!S:S,$B16,'Executive Pay Breakdown'!U:U)+SUMIF('Executive Pay Breakdown'!W:W,$B16,'Executive Pay Breakdown'!Y:Y)+SUMIF('Executive Pay Breakdown'!AA:AA,$B16,'Executive Pay Breakdown'!AC:AC) -> 33531913 | K16: =SUMIF('Executive Pay Breakdown'!K:K,$B16,'Executive Pay Breakdown'!M:M) -> 8565840 | L16: =SUMIF('Executive Pay Breakdown'!O:O,$B16,'Executive Pay Breakdown'!Q:Q) -> 16993744 | M16: =SUMIF('Executive Pay Breakdown'!S:S,$B16,'Executive Pay Breakdown'!U:U) -> 3609960 | N16: =SUMIF('Executive Pay Breakdown'!W:W,$B16,'Executive Pay Breakdown'!Y:Y) -> 2504122 | O16: =SUMIF('Executive Pay Breakdown'!AA:AA,$B16,'Executive Pay Breakdown'!AC:AC) -> 1858247
B17: R. Perreault | C17: UGI | I17: =SUMIF('Executive Pay Breakdown'!K:K,$B17,'Executive Pay Breakdown'!M:M)+SUMIF('Executive Pay Breakdown'!O:O,$B17,'Executive Pay Breakdown'!Q:Q)+SUMIF('Executive Pay Breakdown'!S:S,$B17,'Executive Pay Breakdown'!U:U)+SUMIF('Executive Pay Breakdown'!W:W,$B17,'Executive Pay Breakdown'!Y:Y)+SUMIF('Executive Pay Breakdown'!AA:AA,$B17,'Executive Pay Breakdown'!AC:AC) -> 16723757 | K17: =SUMIF('Executive Pay Breakdown'!K:K,$B17,'Executive Pay Breakdown'!M:M) -> 6060694 | L17: =SUMIF('Executive Pay Breakdown'!O:O,$B17,'Executive Pay Breakdown'!Q:Q) -> 4107789 | M17: =SUMIF('Executive Pay Breakdown'!S:S,$B17,'Executive Pay Breakdown'!U:U) -> 2385873 | N17: =SUMIF('Executive Pay Breakdown'!W:W,$B17,'Executive Pay Breakdown'!Y:Y) -> 2272717 | O17: =SUMIF('Executive Pay Breakdown'!AA:AA,$B17,'Executive Pay Breakdown'!AC:AC) -> 1896684
B18: Vincent Sorgi | C18: PPL | I18: =SUMIF('Executive Pay Breakdown'!K:K,$B18,'Executive Pay Breakdown'!M:M)+SUMIF('Executive Pay Breakdown'!O:O,$B18,'Executive Pay Breakdown'!Q:Q)+SUMIF('Executive Pay Breakdown'!S:S,$B18,'Executive Pay Breakdown'!U:U)+SUMIF('Executive Pay Breakdown'!W:W,$B18,'Executive Pay Breakdown'!Y:Y)+SUMIF('Executive Pay Breakdown'!AA:AA,$B18,'Executive Pay Breakdown'!AC:AC) -> 35944103 | K18: =SUMIF('Executive Pay Breakdown'!K:K,$B18,'Executive Pay Breakdown'!M:M) -> 9146575 | L18: =SUMIF('Executive Pay Breakdown'!O:O,$B18,'Executive Pay Breakdown'!Q:Q) -> 11356481 | M18: =SUMIF('Executive Pay Breakdown'!S:S,$B18,'Executive Pay Breakdown'!U:U) -> 7774443 | N18: =SUMIF('Executive Pay Breakdown'!W:W,$B18,'Executive Pay Breakdown'!Y:Y) -> 4731409 | O18: =SUMIF('Executive Pay Breakdown'!AA:AA,$B18,'Executive Pay Breakdown'!AC:AC) -> 2935195
B19: Gregory P. Lewis | C19: Honeywell International | I19: =SUMIF('Executive Pay Breakdown'!K:K,$B19,'Executive Pay Breakdown'!M:M)+SUMIF('Executive Pay Breakdown'!O:O,$B19,'Executive Pay Breakdown'!Q:Q)+SUMIF('Executive Pay Breakdown'!S:S,$B19,'Executive Pay Breakdown'!U:U)+SUMIF('Executive Pay Breakdown'!W:W,$B19,'Executive Pay Breakdown'!Y:Y)+SUMIF('Executive Pay Breakdown'!AA:AA,$B19,'Executive Pay Breakdown'!AC:AC) -> 32441237 | K19: =SUMIF('Executive Pay Breakdown'!K:K,$B19,'Executive Pay Breakdown'!M:M) -> 7979076 | L19: =SUMIF('Executive Pay Breakdown'!O:O,$B19,'Executive Pay Breakdown'!Q:Q) -> 8379703 | M19: =SUMIF('Executive Pay Breakdown'!S:S,$B19,'Executive Pay Breakdown'!U:U) -> 6831332 | N19: =SUMIF('Executive Pay Breakdown'!W:W,$B19,'Executive Pay Breakdown'!Y:Y) -> 6644633 | O19: =SUMIF('Executive Pay Breakdown'!AA:AA,$B19,'Executive Pay Breakdown'!AC:AC) -> 2606493
B20: Steven E. Strah | C20: FirstEnergy | I20: =SUMIF('Executive Pay Breakdown'!K:K,$B20,'Executive Pay Breakdown'!M:M)+SUMIF('Executive Pay Breakdown'!O:O,$B20,'Executive Pay Breakdown'!Q:Q)+SUMIF('Executive Pay Breakdown'!S:S,$B20,'Executive Pay Breakdown'!U:U)+SUMIF('Executive Pay Breakdown'!W:W,$B20,'Executive Pay Breakdown'!Y:Y)+SUMIF('Executive Pay Breakdown'!AA:AA,$B20,'Executive Pay Breakdown'!AC:AC) -> 26298713 | K20: =SUMIF('Executive Pay Breakdown'!K:K,$B20,'Executive Pay Breakdown'!M:M) -> 8553297 | L20: =SUMIF('Executive Pay Breakdown'!O:O,$B20,'Executive Pay Breakdown'!Q:Q) -> 8837858 | M20: =SUMIF('Executive Pay Breakdown'!S:S,$B20,'Executive Pay Breakdown'!U:U) -> 3264629 | N20: =SUMIF('Executive Pay Breakdown'!W:W,$B20,'Executive Pay Breakdown'!Y:Y) -> 2844406 | O20: =SUMIF('Executive Pay Breakdown'!AA:AA,$B20,'Executive Pay Breakdown'!AC:AC) -> 2798523
B21: John O. Larsen | C21: Alliant Energy | I21: =SUMIF('Executive Pay Breakdown'!K:K,$B21,'Executive Pay Breakdown'!M:M)+SUMIF('Executive Pay Breakdown'!O:O,$B21,'Executive Pay Breakdown'!Q:Q)+SUMIF('Executive Pay Breakdown'!S:S,$B21,'Executive Pay Breakdown'!U:U)+SUMIF('Executive Pay Breakdown'!W:W,$B21,'Executive Pay Breakdown'!Y:Y)+SUMIF('Executive Pay Breakdown'!AA:AA,$B21,'Executive Pay Breakdown'!AC:AC) -> 38829320 | K21: =SUMIF('Executive Pay Breakdown'!K:K,$B21,'Executive Pay Breakdown'!M:M) -> 7286977 | L21: =SUMIF('Executive Pay Breakdown'!O:O,$B21,'Executive Pay Breakdown'!Q:Q) -> 10449260 | M21: =SUMIF('Executive Pay Breakdown'!S:S,$B21,'Executive Pay Breakdown'!U:U) -> 11020134 | N21: =SUMIF('Executive Pay Breakdown'!W:W,$B21,'Executive Pay Breakdown'!Y:Y) -> 7619999 | O21: =SUMIF('Executive Pay Breakdown'!AA:AA,$B21,'Executive Pay Breakdown'!AC:AC) -> 2452950
B22: Stuart A. Arbuckle | C22: Vertex Pharmaceuticals | I22: =SUMIF('Executive Pay Breakdown'!K:K,$B22,'Executive Pay Breakdown'!M:M)+SUMIF('Executive Pay Breakdown'!O:O,$B22,'Executive Pay Breakdown'!Q:Q)+SUMIF('Executive Pay Breakdown'!S:S,$B22,'Executive Pay Breakdown'!U:U)+SUMIF('Executive Pay Breakdown'!W:W,$B22,'Executive Pay Breakdown'!Y:Y)+SUMIF('Executive Pay Breakdown'!AA:AA,$B22,'Executive Pay Breakdown'!AC:AC) -> 42298850 | K22: =SUMIF('Executive Pay Breakdown'!K:K,$B22,'Executive Pay Breakdown'!M:M) -> 14999106 | L22: =SUMIF('Executive Pay Breakdown'!O:O,$B22,'Executive Pay Breakdown'!Q:Q) -> 7810141 | M22: =SUMIF('Executive Pay Breakdown'!S:S,$B22,'Executive Pay Breakdown'!U:U) -> 7282978 | N22: =SUMIF('Executive Pay Breakdown'!W:W,$B22,'Executive Pay Breakdown'!Y:Y) -> 6859533 | O22: =SUMIF('Executive Pay Breakdown'!AA:AA,$B22,'Executive Pay Breakdown'!AC:AC) -> 5347092
B23: J. Kevin Akers | C23: Atmos Energy | I23: =SUMIF('Executive Pay Breakdown'!K:K,$B23,'Executive Pay Breakdown'!M:M)+SUMIF('Executive Pay Breakdown'!O:O,$B23,'Executive Pay Breakdown'!Q:Q)+SUMIF('Executive Pay Breakdown'!S:S,$B23,'Executive Pay Breakdown'!U:U)+SUMIF('Executive Pay Breakdown'!W:W,$B23,'Executive Pay Breakdown'!Y:Y)+SUMIF('Executive Pay Breakdown'!AA:AA,$B23,'Executive Pay Breakdown'!AC:AC) -> 30725684 | K23: =SUMIF('Executive Pay Breakdown'!K:K,$B23,'Executive Pay Breakdown'!M:M) -> 4839562 | L23: =SUMIF('Executive Pay Breakdown'!O:O,$B23,'Executive Pay Breakdown'!Q:Q) -> 6467314 | M23: =SUMIF('Executive Pay Breakdown'!S:S,$B23,'Executive Pay Breakdown'!U:U) -> 9826659 | N23: =SUMIF('Executive Pay Breakdown'!W:W,$B23,'Executive Pay Breakdown'!Y:Y) -> 7855539 | O23: =SUMIF('Executive Pay Breakdown'!AA:AA,$B23,'Executive Pay Breakdown'!AC:AC) -> 1736610
B24: James H. Gallegos | C24: Alliant Energy American Water Works | I24: =SUMIF('Executive Pay Breakdown'!K:K,$B24,'Executive Pay Breakdown'!M:M)+SUMIF('Executive Pay Breakdown'!O:O,$B24,'Executive Pay Breakdown'!Q:Q)+SUMIF('Executive Pay Breakdown'!S:S,$B24,'Executive Pay Breakdown'!U:U)+SUMIF('Executive Pay Breakdown'!W:W,$B24,'Executive Pay Breakdown'!Y:Y)+SUMIF('Executive Pay Breakdown'!AA:AA,$B24,'Executive Pay Breakdown'!AC:AC) -> 12826091 | K24: =SUMIF('Executive Pay Breakdown'!K:K,$B24,'Executive Pay Breakdown'!M:M) -> 4916509 | L24: =SUMIF('Executive Pay Breakdown'!O:O,$B24,'Executive Pay Breakdown'!Q:Q) -> 2129552 | M24: =SUMIF('Executive Pay Breakdown'!S:S,$B24,'Executive Pay Breakdown'!U:U) -> 2062273 | N24: =SUMIF('Executive Pay Breakdown'!W:W,$B24,'Executive Pay Breakdown'!Y:Y) -> 1928911 | O24: =SUMIF('Executive Pay Breakdown'!AA:AA,$B24,'Executive Pay Breakdown'!AC:AC) -> 1788846
B25: John W. Swieringa | C25: DISH Network | I25: =SUMIF('Executive Pay Breakdown'!K:K,$B25,'Executive Pay Breakdown'!M:M)+SUMIF('Executive Pay Breakdown'!O:O,$B25,'Executive Pay Breakdown'!Q:Q)+SUMIF('Executive Pay Breakdown'!S:S,$B25,'Executive Pay Breakdown'!U:U)+SUMIF('Executive Pay Breakdown'!W:W,$B25,'Executive Pay Breakdown'!Y:Y)+SUMIF('Executive Pay Breakdown'!AA:AA,$B25,'Executive Pay Breakdown'!AC:AC) -> 14593228 | K25: =SUMIF('Executive Pay Breakdown'!K:K,$B25,'Executive Pay Breakdown'!M:M) -> 7926917 | L25: =SUMIF('Executive Pay Breakdown'!O:O,$B25,'Executive Pay Breakdown'!Q:Q) -> 1724889 | M25: =SUMIF('Executive Pay Breakdown'!S:S,$B25,'Executive Pay Breakdown'!U:U) -> 1000290 | N25: =SUMIF('Executive Pay Breakdown'!W:W,$B25,'Executive Pay Breakdown'!Y:Y) -> 1018673 | O25: =SUMIF('Executive Pay Breakdown'!AA:AA,$B25,'Executive Pay Breakdown'!AC:AC) -> 2922459
B26: Andrew S. Marsh | C26: Entergy | I26: =SUMIF('Executive Pay Breakdown'!K:K,$B26,'Executive Pay Breakdown'!M:M)+SUMIF('Executive Pay Breakdown'!O:O,$B26,'Executive Pay Breakdown'!Q:Q)+SUMIF('Executive Pay Breakdown'!S:S,$B26,'Executive Pay Breakdown'!U:U)+SUMIF('Executive Pay Breakdown'!W:W,$B26,'Executive Pay Breakdown'!Y:Y)+SUMIF('Executive Pay Breakdown'!AA:AA,$B26,'Executive Pay Breakdown'!AC:AC) -> 24296290 | K26: =SUMIF('Executive Pay Breakdown'!K:K,$B26,'Executive Pay Breakdown'!M:M) -> 6861760 | L26: =SUMIF('Executive Pay Breakdown'!O:O,$B26,'Executive Pay Breakdown'!Q:Q) -> 3889327 | M26: =SUMIF('Executive Pay Breakdown'!S:S,$B26,'Executive Pay Breakdown'!U:U) -> 6007055 | N26: =SUMIF('Executive Pay Breakdown'!W:W,$B26,'Executive Pay Breakdown'!Y:Y) -> 4934063 | O26: =SUMIF('Executive Pay Breakdown'!AA:AA,$B26,'Executive Pay Breakdown'!AC:AC) -> 2604085
... B74: Robert Hoglund | C74: Consolidated Edison | I74: =SUMIF('Executive Pay Breakdown'!K:K,$B74,'Executive Pay Breakdown'!M:M)+SUMIF('Executive Pay Breakdown'!O:O,$B74,'Executive Pay Breakdown'!Q:Q)+SUMIF('Executive Pay Breakdown'!S:S,$B74,'Executive Pay Breakdown'!U:U)+SUMIF('Executive Pay Breakdown'!W:W,$B74,'Executive Pay Breakdown'!Y:Y)+SUMIF('Executive Pay Breakdown'!AA:AA,$B74,'Executive Pay Breakdown'!AC:AC) -> 16166691 | K74: =SUMIF('Executive Pay Breakdown'!K:K,$B74,'Executive Pay Breakdown'!M:M) -> 3643718 | L74: =SUMIF('Executive Pay Breakdown'!O:O,$B74,'Executive Pay Breakdown'!Q:Q) -> 3449763 | M74: =SUMIF('Executive Pay Breakdown'!S:S,$B74,'Executive Pay Breakdown'!U:U) -> 3061602 | N74: =SUMIF('Executive Pay Breakdown'!W:W,$B74,'Executive Pay Breakdown'!Y:Y) -> 3443888 | O74: =SUMIF('Executive Pay Breakdown'!AA:AA,$B74,'Executive Pay Breakdown'!AC:AC) -> 2567720
